<?xml version="1.0" encoding="utf-8"?>
<!-- This URDF was automatically created by SolidWorks to URDF Exporter! Originally created by Stephen Brawner (brawner@gmail.com) 
     Commit Version: 1.6.0-1-g15f4949  Build Version: 1.6.7594.29634
     For more information, please see http://wiki.ros.org/sw_urdf_exporter -->
<robot
  name="Rasbot__3_description">
  <link
    name="base_link">
    <inertial>
      <origin
        xyz="-0.008709 0.00031983 0.011279"
        rpy="0 0 0" />
      <mass
        value="0.42178" />
      <inertia
        ixx="0.00028719"
        ixy="1.1163E-07"
        ixz="-4.1813E-06"
        iyy="0.00048601"
        iyz="9.9782E-08"
        izz="0.00065396" />
    </inertial>
    <visual>
      <origin
        xyz="0 0 0"
        rpy="0 0 0" />
      <geometry>
        <mesh
          filename="package://Rasbot__3_description/meshes/base_link.STL" />
      </geometry>
      <material
        name="azul">
        <color
          rgba="0 0 0.5 1" />
      </material>
    </visual>
    <collision>
      <origin
        xyz="0 0 0"
        rpy="0 0 0" />
      <geometry>
        <mesh
          filename="package://Rasbot__3_description/meshes/base_link.STL" />
      </geometry>
    </collision>
  </link>
  <link
    name="right_wheel">
    <inertial>
      <origin
        xyz="-2.9217E-05 -1.2071E-05 -3.972E-05"
        rpy="0 0 0" />
      <mass
        value="0.012327" />
      <inertia
        ixx="3.5535E-06"
        ixy="-7.5352E-10"
        ixz="-6.7566E-11"
        iyy="3.555E-06"
        iyz="-2.7915E-11"
        izz="6.9784E-06" />
    </inertial>
    <visual>
      <origin
        xyz="0 0 0"
        rpy="0 0 0" />
      <geometry>
        <mesh
          filename="package://Rasbot__3_description/meshes/right_wheel.STL" />
      </geometry>
      <material
        name="gris">
        <color
          rgba="0.25098 0.25098 0.25098 1" />
      </material>
    </visual>
    <collision>
      <origin
        xyz="0 0 0"
        rpy="0 0 0" />
      <geometry>
        <mesh
          filename="package://Rasbot__3_description/meshes/right_wheel.STL" />
      </geometry>
    </collision>
  </link>
  <joint
    name="base_right_wheel_joint"
    type="continuous">
    <origin
      xyz="0.03084 0.051547 -0.0148"
      rpy="-1.5708 0 0" />
    <parent
      link="base_link" />
    <child
      link="right_wheel" />
    <axis
      xyz="0 0 -1" />
    <limit
      effort="0.4"
      velocity="2" />
  </joint>
  <link
    name="left_wheel">
    <inertial>
      <origin
        xyz="-8.8818E-15 3.1613E-05 -3.972E-05"
        rpy="0 0 0" />
      <mass
        value="0.012327" />
      <inertia
        ixx="3.5553E-06"
        ixy="1.4381E-19"
        ixz="-9.462E-19"
        iyy="3.5532E-06"
        iyz="7.3105E-11"
        izz="6.9784E-06" />
    </inertial>
    <visual>
      <origin
        xyz="0 0 0"
        rpy="0 0 0" />
      <geometry>
        <mesh
          filename="package://Rasbot__3_description/meshes/left_wheel.STL" />
      </geometry>
      <material
        name="gris">
        <color
          rgba="0.25098 0.25098 0.25098 1" />
      </material>
    </visual>
    <collision>
      <origin
        xyz="0 0 0"
        rpy="0 0 0" />
      <geometry>
        <mesh
          filename="package://Rasbot__3_description/meshes/left_wheel.STL" />
      </geometry>
    </collision>
  </link>
  <joint
    name="base_left_wheel_joint"
    type="continuous">
    <origin
      xyz="0.03084 -0.051547 -0.0148"
      rpy="1.5708 0 0" />
    <parent
      link="base_link" />
    <child
      link="left_wheel" />
    <axis
      xyz="0 0 -1" />
    <limit
      effort="0.4"
      velocity="2" />
  </joint>
  <link
    name="base_cam_link">
    <inertial>
      <origin
        xyz="0.0079827 5.4286E-05 0.014985"
        rpy="0 0 0" />
      <mass
        value="0.015993" />
      <inertia
        ixx="1.8893E-06"
        ixy="-1.7136E-07"
        ixz="-3.8471E-07"
        iyy="2.2804E-06"
        iyz="-3.8442E-07"
        izz="2.667E-06" />
    </inertial>
    <visual>
      <origin
        xyz="0 0 0"
        rpy="0 0 0" />
      <geometry>
        <mesh
          filename="package://Rasbot__3_description/meshes/base_cam_link.STL" />
      </geometry>
      <material
        name="azul_2">
        <color
          rgba="0 0 1 1" />
      </material>
    </visual>
    <collision>
      <origin
        xyz="0 0 0"
        rpy="0 0 0" />
      <geometry>
        <mesh
          filename="package://Rasbot__3_description/meshes/base_cam_link.STL" />
      </geometry>
    </collision>
  </link>
  <joint
    name="base_base_cam_joint"
    type="revolute">
    <origin
      xyz="0.041348 0 0.033526"
      rpy="0 0 0" />
    <parent
      link="base_link" />
    <child
      link="base_cam_link" />
    <axis
      xyz="0 0 -1" />
    <limit
      lower="-1.5708"
      upper="1.5708"
      effort="0.1"
      velocity="1" />
  </joint>
  <link
    name="camera_link">
    <inertial>
      <origin
        xyz="0.0031771 -0.00025892 0.0033658"
        rpy="0 0 0" />
      <mass
        value="0.011488" />
      <inertia
        ixx="9.9215E-07"
        ixy="2.2492E-08"
        ixz="-7.2374E-09"
        iyy="7.6855E-07"
        iyz="1.3763E-08"
        izz="4.5939E-07" />
    </inertial>
    <visual>
      <origin
        xyz="0 0 0"
        rpy="0 0 0" />
      <geometry>
        <mesh
          filename="package://Rasbot__3_description/meshes/camera_link.STL" />
      </geometry>
      <material
        name="verde">
        <color
          rgba="0 0.75294 0 1" />
      </material>
    </visual>
    <collision>
      <origin
        xyz="0 0 0"
        rpy="0 0 0" />
      <geometry>
        <mesh
          filename="package://Rasbot__3_description/meshes/camera_link.STL" />
      </geometry>
    </collision>
  </link>
  <joint
    name="base_cam_camera_joint"
    type="revolute">
    <origin
      xyz="0.022875 0.0004 0.038592"
      rpy="0 0 0" />
    <parent
      link="base_cam_link" />
    <child
      link="camera_link" />
    <axis
      xyz="0 -1 0" />
    <limit
      lower="-1.5708"
      upper="1.5708"
      effort="0.1"
      velocity="1" />
  </joint>
</robot>